Workbook

Sheet Přehled
A1: Portu – přehled všech portfolií a přímých pozic (přepočet k 21.7.2026)
A2: Kurzy: 1 USD = 21,20 Kč, 1 EUR = 24,19 Kč (zadáno klientem). Setříděno od nejvyšší hodnoty. Desetinná tečka; % na 1 des. místo.
A4: Portfolio | B4: Instrument (název + ticker/ISIN) | C4: Původní měna | D4: Hodnota (pův. měna) | E4: Hodnota v CZK | F4: Podíl na celku
A5: WOOD realitní fond 1 | B5: Realitní fond | C5: CZK | D5: 1387318 | E5: =D5 -> 1387318 | F5: =E5/$E$19 -> 0.36819987
A6: Investiční rezerva 3 | B6: Investiční rezerva – Opatrnější | C6: CZK | D6: 429100 | E6: =D6 -> 429100 | F6: =E6/$E$19 -> 0.11388489
A7: Technologický pokrok | B7: Portfolio podle vás | C7: CZK | D7: 369138.23 | E7: =D7 -> 369138.23 | F7: =E7/$E$19 -> 0.097970796
A8: Víra v hodnotu | B8: Portfolio podle vás | C8: CZK | D8: 309592.58 | E8: =D8 -> 309592.58 | F8: =E8/$E$19 -> 0.082167137
A9: Investiční rezerva 2 | B9: Investiční rezerva – Opatrnější | C9: CZK | D9: 268672 | E9: =D9 -> 268672 | F9: =E9/$E$19 -> 0.071306648
A10: Druhá strategie M | B10: Portfolio podle vás | C10: CZK | D10: 259883.66 | E10: =D10 -> 259883.66 | F10: =E10/$E$19 -> 0.068974186
A11: Třetí strategie | B11: Portfolio podle vás | C11: CZK | D11: 169250.12 | E11: =D11 -> 169250.12 | F11: =E11/$E$19 -> 0.044919674
A12: Čtvrtá strategie | B12: Portfolio podle vás | C12: CZK | D12: 144091.7 | E12: =D12 -> 144091.7 | F12: =E12/$E$19 -> 0.038242526
A13: Moje první portfolio | B13: Portfolio podle vás | C13: CZK | D13: 138953.89 | E13: =D13 -> 138953.89 | F13: =E13/$E$19 -> 0.036878931
A14: DOOSAN Škoda Power | B14: DSPW CP · 191 ks (Moje instrumenty) | C14: CZK | D14: 89865.5 | E14: =D14 -> 89865.5 | F14: =E14/$E$19 -> 0.023850671
A15: Investiční rezerva 1 | B15: Investiční rezerva – Odvážnější | C15: CZK | D15: 80439 | E15: =D15 -> 80439 | F15: =E15/$E$19 -> 0.02134884
A16: 1. J&T WOOD Defense – OPF | B16: Fond | C16: CZK | D16: 55561 | E16: =D16 -> 55561 | F16: =E16/$E$19 -> 0.014746117
A17: První Crypto investice | B17: Portfolio podle vás | C17: CZK | D17: 33896.38 | E17: =D17 -> 33896.38 | F17: =E17/$E$19 -> 0.0089962379
A18: Czechoslovak Group (CSG) | B18: CSG NA · 90 ks (Moje instrumenty) | C18: EUR | D18: 1326.06 | E18: =D18*Kurzy!$B$5 -> 32077.391 | F18: =E18/$E$19 -> 0.0085134709
A19: CELKEM | E19: =SUM(E5:E18) -> 3767839.5 | F19: =SUM(F5:F18) -> 1
A21: Zeleně = MANTINELY (nedotýkat se; do součtu a % se ale počítají): realitní fond a Investiční rezervy 1–3.
A22: Sekce Moje oblibene na printscreenu (Alphabet, Amazon, Caterpillar, iShares Automation&Robotics, iShares Bitcoin ETP, Komercni banka, WisdomTree AI) je WATCHLIST, ne drzene pozice - nezapocitano.

Sheet Detail
A1: Detail viditelných složek portfolií
A2: POZOR: zobrazeny jen složky viditelné na printscreenech. Každé portfolio má i další nezobrazené složky (cca 2–3 %), proto součet složek < celková hodnota portfolia (viz list Prehled). Hodnoty složek jsou vnitřní podíly portfolia – NEsčítají se do celku znovu, celkovou hodnotu drží list Prehled.
A4: Portfolio | B4: Instrument / složka | C4: Původní měna | D4: Hodnota (pův. měna) | E4: Hodnota v CZK | F4: Zastoupení v portfoliu | G4: Podíl na celku
A5: Moje první portfolio | B5: Americké akcie (S&P 500) | C5: USD | D5: 2218.43 | E5: =D5*Kurzy!$B$4 -> 47030.716 | F5: 0.338 | G5: =E5/Přehled!$E$19 -> 0.012482144
A6: Moje první portfolio | B6: Globální akcie malých společností | C6: EUR | D6: 877.49 | E6: =D6*Kurzy!$B$5 -> 21226.483 | F6: 0.1526 | G6: =E6/Přehled!$E$19 -> 0.0056335954
A7: Moje první portfolio | B7: Evropské akcie | C7: EUR | D7: 869.94 | E7: =D7*Kurzy!$B$5 -> 21043.849 | F7: 0.1513 | G7: =E7/Přehled!$E$19 -> 0.0055851235
A8: Moje první portfolio | B8: Krátkodobé US treasuries (1-3 roky) | C8: USD | D8: 538.92 | E8: =D8*Kurzy!$B$4 -> 11425.104 | F8: 0.0821 | G8: =E8/Přehled!$E$19 -> 0.0030322693
A9: Moje první portfolio | B9: Japonské akcie – EUR hgd | C9: EUR | D9: 466.57 | E9: =D9*Kurzy!$B$5 -> 11286.328 | F9: 0.0811 | G9: =E9/Přehled!$E$19 -> 0.0029954377
A10: Moje první portfolio | B10: Nemovitostní společnosti (globální) | C10: EUR | D10: 390.52 | E10: =D10*Kurzy!$B$5 -> 9446.6788 | F10: 0.0679 | G10: =E10/Přehled!$E$19 -> 0.0025071872
A11: Moje první portfolio | B11: Asijské akcie | C11: EUR | D11: 239.74 | E11: =D11*Kurzy!$B$5 -> 5799.3106 | F11: 0.0417 | G11: =E11/Přehled!$E$19 -> 0.0015391608
A12: Moje první portfolio | B12: Akcie rozvojových zemí | C12: EUR | D12: 234.58 | E12: =D12*Kurzy!$B$5 -> 5674.4902 | F12: 0.0408 | G12: =E12/Přehled!$E$19 -> 0.0015060329
A13: Moje první portfolio | B13: Globální inflačně vázané dluhopisy | C13: USD | D13: 178.53 | E13: =D13*Kurzy!$B$4 -> 3784.836 | F13: 0.0272 | G13: =E13/Přehled!$E$19 -> 0.001004511
A14: Technologický pokrok | B14: IT sektor (USA) | C14: USD | D14: 2982.96 | E14: =D14*Kurzy!$B$4 -> 63238.752 | F14: 0.1711 | G14: =E14/Přehled!$E$19 -> 0.016783823
A15: Technologický pokrok | B15: Automatizace a robotika | C15: EUR | D15: 1904.45 | E15: =D15*Kurzy!$B$5 -> 46068.646 | F15: 0.1247 | G15: =E15/Přehled!$E$19 -> 0.012226807
A16: Technologický pokrok | B16: Polovodiče | C16: EUR | D16: 1636.72 | E16: =D16*Kurzy!$B$5 -> 39592.257 | F16: 0.1071 | G16: =E16/Přehled!$E$19 -> 0.010507947
A17: Technologický pokrok | B17: Krátkodobé US treasuries (0-1 rok) | C17: USD | D17: 2136.31 | E17: =D17*Kurzy!$B$4 -> 45289.772 | F17: 0.1225 | G17: =E17/Přehled!$E$19 -> 0.012020091
A18: Technologický pokrok | B18: 3M | C18: USD | D18: 1571.61 | E18: =D18*Kurzy!$B$4 -> 33318.132 | F18: 0.0901 | G18: =E18/Přehled!$E$19 -> 0.0088427685
A19: Technologický pokrok | B19: Paměťové čipy | C19: EUR | D19: 1251.3 | E19: =D19*Kurzy!$B$5 -> 30268.947 | F19: 0.0819 | G19: =E19/Přehled!$E$19 -> 0.0080335023
A20: Technologický pokrok | B20: Elektromobilita | C20: EUR | D20: 1004.27 | E20: =D20*Kurzy!$B$5 -> 24293.291 | F20: 0.0657 | G20: =E20/Přehled!$E$19 -> 0.0064475389
A21: Technologický pokrok | B21: Kybernetická bezpečnost | C21: USD | D21: 1221.27 | E21: =D21*Kurzy!$B$4 -> 25890.924 | F21: 0.07 | G21: =E21/Přehled!$E$19 -> 0.0068715571
A22: Technologický pokrok | B22: Pfizer | C22: USD | D22: 1064.12 | E22: =D22*Kurzy!$B$4 -> 22559.344 | F22: 0.061 | G22: =E22/Přehled!$E$19 -> 0.0059873422
A23: Technologický pokrok | B23: Biotechnologie a farmacie (USA) | C23: USD | D23: 936.08 | E23: =D23*Kurzy!$B$4 -> 19844.896 | F23: 0.0537 | G23: =E23/Přehled!$E$19 -> 0.0052669166
A24: Technologický pokrok | B24: Starbucks | C24: USD | D24: 555.66 | E24: =D24*Kurzy!$B$4 -> 11779.992 | F24: 0.0319 | G24: =E24/Přehled!$E$19 -> 0.0031264581
A25: Víra v hodnotu | B25: Americké akcie "wide moat" (ESG) | C25: USD | D25: 2347.61 | E25: =D25*Kurzy!$B$4 -> 49769.332 | F25: 0.1605 | G25: =E25/Přehled!$E$19 -> 0.013208984
A26: Víra v hodnotu | B26: Dividendové akcie (rozvoj. země) | C26: EUR | D26: 2096.37 | E26: =D26*Kurzy!$B$5 -> 50711.19 | F26: 0.1636 | G26: =E26/Přehled!$E$19 -> 0.013458957
A27: Víra v hodnotu | B27: Globální dividendové akcie | C27: EUR | D27: 2354.4 | E27: =D27*Kurzy!$B$5 -> 56952.936 | F27: 0.161 | G27: =E27/Přehled!$E$19 -> 0.015115542
A28: Víra v hodnotu | B28: Krátkodobé US treasuries (0-1 rok) | C28: USD | D28: 1486.83 | E28: =D28*Kurzy!$B$4 -> 31520.796 | F28: 0.1017 | G28: =E28/Přehled!$E$19 -> 0.0083657482
A29: Víra v hodnotu | B29: Britské akcie (top 100) | C29: EUR | D29: 1182.35 | E29: =D29*Kurzy!$B$5 -> 28601.047 | F29: 0.0923 | G29: =E29/Přehled!$E$19 -> 0.0075908347
A30: Víra v hodnotu | B30: Evropské akcie (top 50) | C30: EUR | D30: 792.62 | E30: =D30*Kurzy!$B$5 -> 19173.478 | F30: 0.0619 | G30: =E30/Přehled!$E$19 -> 0.0050887194
A31: Víra v hodnotu | B31: Finanční sektor (USA) | C31: USD | D31: 852.51 | E31: =D31*Kurzy!$B$4 -> 18073.212 | F31: 0.0583 | G31: =E31/Přehled!$E$19 -> 0.0047967044
A32: Víra v hodnotu | B32: Private equity společnosti | C32: USD | D32: 764.99 | E32: =D32*Kurzy!$B$4 -> 16217.788 | F32: 0.0523 | G32: =E32/Přehled!$E$19 -> 0.0043042673
A33: Víra v hodnotu | B33: Amazon | C33: USD | D33: 895.81 | E33: =D33*Kurzy!$B$4 -> 18991.172 | F33: 0.0613 | G33: =E33/Přehled!$E$19 -> 0.0050403347
A34: Víra v hodnotu | B34: Komodity (CMCI) | C34: EUR | D34: 735.14 | E34: =D34*Kurzy!$B$5 -> 17783.037 | F34: 0.0574 | G34: =E34/Přehled!$E$19 -> 0.0047196906
A35: Čtvrtá strategie | B35: Colt | C35: CZK | D35: 25287.97 | E35: =D35 -> 25287.97 | F35: 0.1755 | G35: =E35/Přehled!$E$19 -> 0.0067115307
A36: Čtvrtá strategie | B36: Johnson & Johnson | C36: USD | D36: 947.9 | E36: =D36*Kurzy!$B$4 -> 20095.48 | F36: 0.1393 | G36: =E36/Přehled!$E$19 -> 0.0053334226
A37: Čtvrtá strategie | B37: Verizon | C37: USD | D37: 875.18 | E37: =D37*Kurzy!$B$4 -> 18553.816 | F37: 0.1286 | G37: =E37/Přehled!$E$19 -> 0.0049242586
A38: Čtvrtá strategie | B38: Coca-Cola | C38: USD | D38: 837.61 | E38: =D38*Kurzy!$B$4 -> 17757.332 | F38: 0.1231 | G38: =E38/Přehled!$E$19 -> 0.0047128685
A39: Čtvrtá strategie | B39: IBM | C39: USD | D39: 729.46 | E39: =D39*Kurzy!$B$4 -> 15464.552 | F39: 0.1072 | G39: =E39/Přehled!$E$19 -> 0.0041043553
A40: Čtvrtá strategie | B40: Apple | C40: USD | D40: 514.77 | E40: =D40*Kurzy!$B$4 -> 10913.124 | F40: 0.0756 | G40: =E40/Přehled!$E$19 -> 0.0028963877
A41: Čtvrtá strategie | B41: P&G | C41: USD | D41: 507.79 | E41: =D41*Kurzy!$B$4 -> 10765.148 | F41: 0.0746 | G41: =E41/Přehled!$E$19 -> 0.0028571143
...

Sheet Překryvy
A1: Překryvy a duplicitní expozice napříč portfolii
A2: Stejný / velmi podobný instrument sečtený napříč portfolii. CZK přes kurzy z listu Kurzy. % z celku (list Přehled).
A4: Instrument / expozice | B4: Ve kterých portfoliích (počet) | C4: Hodnota v CZK (součet) | D4: Podíl na celku
A5: Colt (zbrojní akcie) – DUPLICITA | B5: Čtvrtá strategie + Třetí strategie (2×) | C5: =25287.97+23602.85 -> 48890.82 | D5: =C5/Přehled!$E$19 -> 0.012975824
A6: Czechoslovak Group (CSG) – DUPLICITA | B6: Moje instrumenty (přímo) + První Crypto investice (2×) | C6: =1326.06*Kurzy!$B$5+281.48*Kurzy!$B$5 -> 38886.393 | D6: =C6/Přehled!$E$19 -> 0.010320608
A7: Americké akcie (S&P 500) – DUPLICITA | B7: Moje první portfolio + Druhá strategie M (2×) | C7: =2218.43*Kurzy!$B$4+854.46*Kurzy!$B$4 -> 65145.268 | D7: =C7/Přehled!$E$19 -> 0.017289821
A8: Krátkodobé US treasuries – VÍCENÁSOBNÝ PŘEKRYV | B8: Moje první + Technologický + Víra v hodnotu + Třetí + Druhá (5×) | C8: =(538.92+2136.31+1486.83+628.37+1844.82)*Kurzy!$B$4 -> 140667.3 | D8: =C8/Přehled!$E$19 -> 0.037333677
A9: Evropské akcie (podobná expozice) | B9: Moje první + Víra v hodnotu (top50) + Třetí + Druhá (multifaktor) (4×) | C9: =(869.94+792.62+471.61+756.67)*Kurzy!$B$5 -> 69929.42 | D9: =C9/Přehled!$E$19 -> 0.018559554
A10: Globální High Yield dluhopisy | B10: Třetí strategie + Druhá strategie M (2×) | C10: =(623.39+610.19)*Kurzy!$B$4 -> 26151.896 | D10: =C10/Přehled!$E$19 -> 0.0069408202
A11: Bitcoin – dvojí expozice v jednom portfoliu | B11: První Crypto investice: přímý BTC + VanEck BTC ETP | C11: =(228.03+133.89)*Kurzy!$B$5 -> 8754.8448 | D11: =C11/Přehled!$E$19 -> 0.0023235716
A13: TEMATICKÁ KONCENTRACE – obrana / zbrojení (napříč vším)
A14: DOOSAN Škoda Power (přímo) | B14: Moje instrumenty | C14: =89865.5 -> 89865.5 | D14: =C14/Přehled!$E$19 -> 0.023850671
A15: Colt (2×) | B15: Čtvrtá + Třetí strategie | C15: =25287.97+23602.85 -> 48890.82 | D15: =C15/Přehled!$E$19 -> 0.012975824
A16: Czechoslovak Group (2×) | B16: Přímo + První Crypto | C16: =1326.06*Kurzy!$B$5+281.48*Kurzy!$B$5 -> 38886.393 | D16: =C16/Přehled!$E$19 -> 0.010320608
A17: 1. J&T WOOD Defense – OPF | B17: Fond | C17: =55561 -> 55561 | D17: =C17/Přehled!$E$19 -> 0.014746117
A18: Letecký a obranný průmysl | B18: První Crypto investice | C18: =258.33*Kurzy!$B$5 -> 6249.0027 | D18: =C18/Přehled!$E$19 -> 0.0016585109
A19: Obrana a kyberbezpečnost (NATO) | B19: Třetí strategie | C19: =779.11*Kurzy!$B$4 -> 16517.132 | D19: =C19/Přehled!$E$19 -> 0.0043837144
A20: Obranný blok CELKEM | C20: =SUM(C14:C19) -> 255969.85 | D20: =C20/Přehled!$E$19 -> 0.067935444
A22: Pozn.: Watchlist Moje oblibene obsahuje i Amazon (drzen ve Vira v hodnotu) a Komercni banku (drzena ve Ctvrta strategie) - jde jen o sledovane, ne dalsi pozice.
A23: Pozn.: Tech/AI motiv se prolíná napříč Technologický pokrok, Druhá strategie M (AI & Big Data) a watchlistem (iShares Automation&Robotics, WisdomTree AI) – podobná, ne identická expozice.

Sheet Kurzy
A1: Přepočet měn – použité kurzy
A3: Datum | B3: 21. 7. 2026
A4: 1 USD = | B4: 21.2
A5: 1 EUR = | B5: 24.19
A6: Měna přepočtu | B6: CZK
A7: Zdroj | B7: Orientačně odpovídá kurzu ČNB/trhu k 21.7.2026 (dolar ~21,2 Kč, euro ~24,2 Kč).
A9: Pozn.: Hodnoty portfolií Portu jsou vykazovány v Kč; přepočet se týká jen složek a přímých pozic vedených v USD/EUR.
